<robot name="mast">

	<material name="Black">
    	<color rgba="0 0 0 1"/>
	</material>
	<material name="Aqua">
    	<color rgba="0 255 255 1"/>
	</material>

	<link name="base_link">
		  <inertial>
		    <mass value="5"/>
		    <inertia
		      ixx = "0.21666666666666667"
		      iyy = "0.8416666666666667"
		      izz = "1.0416666666666667"
		      ixy = "0"
		      ixz = "0"
		      iyz = "0"
		    />
		  </inertial>
			<material name="Aqua"/>
		  <collision>
		    <geometry>
					<box size="0.40 0.10 0.07"/>
		    </geometry>
				<origin rpy="0 0 0" xyz="0 0 0.075"/>
		  </collision>
		  <visual>
		    <geometry>
		      <box size="0.40 0.10 0.07"/>
		    </geometry>
				<origin rpy="0 0 0" xyz="0 0 0.075"/>
		  </visual>
	</link>

	<!--link name="wheel_front_virtual"/-->	
	<!--link name="wheel_back_virtual"/>	
		<inertial>
      <mass value="0.020"/>
			<inertia
        ixx = "0.0030791666666666667"
        iyy = "0.0030791666666666667"
        izz = "0.005625"
        ixy = "0"
        ixz = "0"
        iyz = "0"
      />
    </inertial-->

	<link name="front_wheel_axis_left">
		<inertial>
      <mass value="0.01"/>
      <inertia ixx="0.01" ixy="0.0" ixz="0.0" iyy="0.01" iyz="0.0" izz="0.01"/>
    </inertial>
    <visual>
      <geometry>
        <cylinder length="0.04" radius="0.005"/>
      </geometry>
    </visual>
    <collision>
      <geometry>
        <cylinder length="0.04" radius="0.005"/>
      </geometry>
    </collision>
	</link>

	<link name="front_wheel_axis_right">
		<inertial>
      <mass value="0.01"/>
      <inertia ixx="0.01" ixy="0.0" ixz="0.0" iyy="0.01" iyz="0.0" izz="0.01"/>
    </inertial>
    <visual>
      <geometry>
        <cylinder length="0.04" radius="0.005"/>
      </geometry>
    </visual>
    <collision>
      <geometry>
        <cylinder length="0.04" radius="0.005"/>
      </geometry>
    </collision>
	</link>

  <link name="wheel_front_left">	
    <inertial>
      <mass value="0.020"/>
			<inertia
        ixx = "0.0030791666666666667"
        iyy = "0.0030791666666666667"
        izz = "0.005625"
        ixy = "0"
        ixz = "0"
        iyz = "0"
      />
    </inertial>
		<material name="Black"/>
    <collision>
      <geometry>
        <cylinder length="0.025" radius="0.035"/>
      </geometry>
    </collision>
    <visual>
      <geometry>
        <cylinder length="0.025" radius="0.035"/>
      </geometry>
    </visual>
  </link>

  <link name="wheel_front_right">	
    <inertial>
      <mass value="0.020"/>
			<inertia
        ixx = "0.0030791666666666667"
        iyy = "0.0030791666666666667"
        izz = "0.005625"
        ixy = "0"
        ixz = "0"
        iyz = "0"
      />
    </inertial>
		<material name="Black"/>
    <collision>
      <geometry>
        <cylinder length="0.025" radius="0.035"/>
      </geometry>
    </collision>
    <visual>
      <geometry>
        <cylinder length="0.025" radius="0.035"/>
      </geometry>
    </visual>
  </link>

  <link name="wheel_back_left">
    <inertial>
      <mass value="0.020"/>
			<inertia
        ixx = "0.0030791666666666667"
        iyy = "0.0030791666666666667"
        izz = "0.005625"
        ixy = "0"
        ixz = "0"
        iyz = "0"
      />
    </inertial>
		<material name="Black"/>
    <collision>
      <geometry>
        <cylinder length="0.025" radius="0.035"/>
      </geometry>
    </collision>
    <visual>
      <geometry>
        <cylinder length="0.025" radius="0.035"/>
      </geometry>
    </visual>
  </link>

	<link name="wheel_back_right">
    <inertial>
      <mass value="0.020"/>
			<inertia
        ixx = "0.0030791666666666667"
        iyy = "0.0030791666666666667"
        izz = "0.005625"
        ixy = "0"
        ixz = "0"
        iyz = "0"
      />
    </inertial>
		<material name="Black"/>
		<collision>
      <geometry>
        <cylinder length="0.025" radius="0.035"/>
      </geometry>
    </collision>
		<visual>
      <geometry>
        <cylinder length="0.025" radius="0.035"/>
      </geometry>
    </visual>
  </link>

	<!--joint name="wheel_front_steer" type="revolute">
    <parent link="base_link"/>
  	<child link="wheel_front_virtual"/>
		<origin rpy="1.5707963267948966 0 0" xyz="0.13 0 0.035"/>
    <axis xyz="0 1 0"/>
		<limit effort="1000.0" lower="-0.49" upper="0.49" velocity="0.5"/>
	</joint-->

	<!--joint name="wheel_back_spin" type="continuous">
    <parent link="base_link"/>
  	<child link="wheel_back_virtual"/>
		<origin rpy="1.5707963267948966 0 0" xyz="-0.13 0 0.035"/>
    <axis xyz="0 0 1"/>
	</joint-->

	<joint name="front_wheel_left_steer" type="revolute">
    <parent link="base_link"/>
  	<child link="front_wheel_axis_left"/>
		<origin rpy="1.57079633 0 0" xyz="0.13 0.0665 0.035"/>
    <axis xyz="0 1 0"/>
		<limit effort="1000.0" lower="-0.49" upper="0.49" velocity="0.5"/>
		<!--mimic joint="wheel_front_steer" multiplier="1" offset="0.0" /-->
  </joint>

	<joint name="front_wheel_right_steer" type="revolute">
    <parent link="base_link"/>
  	<child link="front_wheel_axis_right"/>
		<origin rpy="1.57079633 0 0" xyz="0.13 -0.0665 0.035"/>
    <axis xyz="0 1 0"/>
		<limit effort="1000.0" lower="-0.49" upper="0.49" velocity="0.5"/>
		<mimic joint="front_wheel_left_steer" multiplier="1" offset="0.0"/>
  </joint>

	<joint name="wheel_front_left_spin" type="continuous">
    <parent link="front_wheel_axis_left"/>
  	<child link="wheel_front_left"/>
    <origin rpy="0 0 0" xyz="0 0 -0.02"/>
    <axis xyz="0 0 1"/>
		<mimic joint="wheel_back_right_spin" multiplier="1" offset="0" />
  </joint>

	<joint name="wheel_front_right_spin" type="continuous">
    <parent link="front_wheel_axis_right"/>
  	<child link="wheel_front_right"/>
    <origin rpy="0 0 0" xyz="0 0 0.02"/>
    <axis xyz="0 0 1"/>
		<mimic joint="wheel_back_right_spin" multiplier="1" offset="0" />
  </joint>
	
	<joint name="wheel_back_left_spin" type="continuous">
    <parent link="base_link"/>
  	<child link="wheel_back_left"/>
		<origin rpy="1.5707963267948966 0 0" xyz="-0.13 0.0865 0.035"/>
    <axis xyz="0 0 1"/>
		<mimic joint="wheel_back_right_spin" multiplier="1" offset="0" />
	</joint>

	<joint name="wheel_back_right_spin" type="continuous">
    <parent link="base_link"/>
    <child link="wheel_back_right"/>
		<origin rpy="1.5707963267948966 0 0" xyz="-0.13 -0.0865 0.035"/>
    <axis xyz="0 0 1"/>
		<!--mimic joint="wheel_back_spin" multiplier="1" offset="0" /-->
  </joint>

	<gazebo>
    <plugin name="gazebo_ros_control" filename="libgazebo_ros_control.so">
      <robotNamespace>/mast</robotNamespace>
    </plugin>
  </gazebo>

  <transmission name="speed_is">
    <type>transmission_interface/SimpleTransmission</type>
    <actuator name="speed_motor">
      <mechanicalReduction>1</mechanicalReduction>
    </actuator>
    <joint name="wheel_back_right_spin">
      <hardwareInterface>VelocityJointInterface</hardwareInterface>
    </joint>
  </transmission>

	<transmission name="steering_is">
    <type>transmission_interface/SimpleTransmission</type>
    <actuator name="servo_left">
      <mechanicalReduction>1</mechanicalReduction>
    </actuator>
    <joint name="front_wheel_left_steer">
      <hardwareInterface>PositionJointInterface</hardwareInterface>
    </joint>
  </transmission>


</robot>
